Traceback (most recent call last):
  File "/home/laura/.local/lib/python3.10/site-packages/jupyter_cache/executors/utils.py", line 51, in single_nb_execution
    executenb(
  File "/home/laura/.local/lib/python3.10/site-packages/nbclient/client.py", line 1204, in execute
    return NotebookClient(nb=nb, resources=resources, km=km, **kwargs).execute()
  File "/home/laura/.local/lib/python3.10/site-packages/nbclient/util.py", line 84, in wrapped
    return just_run(coro(*args, **kwargs))
  File "/home/laura/.local/lib/python3.10/site-packages/nbclient/util.py", line 62, in just_run
    return loop.run_until_complete(coro)
  File "/usr/lib/python3.10/asyncio/base_events.py", line 646, in run_until_complete
    return future.result()
  File "/home/laura/.local/lib/python3.10/site-packages/nbclient/client.py", line 663, in async_execute
    await self.async_execute_cell(
  File "/home/laura/.local/lib/python3.10/site-packages/nbclient/client.py", line 965, in async_execute_cell
    await self._check_raise_for_error(cell, cell_index, exec_reply)
  File "/home/laura/.local/lib/python3.10/site-packages/nbclient/client.py", line 862, in _check_raise_for_error
    raise CellExecutionError.from_cell_and_msg(cell, exec_reply_content)
nbclient.exceptions.CellExecutionError: An error occurred while executing the following cell:
------------------
data = MakeSens.download_data('E2_00021', fechaInicio, fechaFin, 'h')
  
------------------

[0;31m---------------------------------------------------------------------------[0m
[0;31mgaierror[0m                                  Traceback (most recent call last)
File [0;32m/usr/lib/python3.10/site-packages/urllib3/connection.py:174[0m, in [0;36mHTTPConnection._new_conn[0;34m(self)[0m
[1;32m    173[0m [38;5;28;01mtry[39;00m:
[0;32m--> 174[0m     conn [38;5;241m=[39m [43mconnection[49m[38;5;241;43m.[39;49m[43mcreate_connection[49m[43m([49m
[1;32m    175[0m [43m        [49m[43m([49m[38;5;28;43mself[39;49m[38;5;241;43m.[39;49m[43m_dns_host[49m[43m,[49m[43m [49m[38;5;28;43mself[39;49m[38;5;241;43m.[39;49m[43mport[49m[43m)[49m[43m,[49m[43m [49m[38;5;28;43mself[39;49m[38;5;241;43m.[39;49m[43mtimeout[49m[43m,[49m[43m [49m[38;5;241;43m*[39;49m[38;5;241;43m*[39;49m[43mextra_kw[49m
[1;32m    176[0m [43m    [49m[43m)[49m
[1;32m    178[0m [38;5;28;01mexcept[39;00m SocketTimeout:

File [0;32m/usr/lib/python3.10/site-packages/urllib3/util/connection.py:72[0m, in [0;36mcreate_connection[0;34m(address, timeout, source_address, socket_options)[0m
[1;32m     68[0m     [38;5;28;01mreturn[39;00m six[38;5;241m.[39mraise_from(
[1;32m     69[0m         LocationParseError([38;5;124mu[39m[38;5;124m"[39m[38;5;124m'[39m[38;5;132;01m%s[39;00m[38;5;124m'[39m[38;5;124m, label empty or too long[39m[38;5;124m"[39m [38;5;241m%[39m host), [38;5;28;01mNone[39;00m
[1;32m     70[0m     )
[0;32m---> 72[0m [38;5;28;01mfor[39;00m res [38;5;129;01min[39;00m [43msocket[49m[38;5;241;43m.[39;49m[43mgetaddrinfo[49m[43m([49m[43mhost[49m[43m,[49m[43m [49m[43mport[49m[43m,[49m[43m [49m[43mfamily[49m[43m,[49m[43m [49m[43msocket[49m[38;5;241;43m.[39;49m[43mSOCK_STREAM[49m[43m)[49m:
[1;32m     73[0m     af, socktype, proto, canonname, sa [38;5;241m=[39m res

File [0;32m/usr/lib/python3.10/socket.py:955[0m, in [0;36mgetaddrinfo[0;34m(host, port, family, type, proto, flags)[0m
[1;32m    954[0m addrlist [38;5;241m=[39m []
[0;32m--> 955[0m [38;5;28;01mfor[39;00m res [38;5;129;01min[39;00m [43m_socket[49m[38;5;241;43m.[39;49m[43mgetaddrinfo[49m[43m([49m[43mhost[49m[43m,[49m[43m [49m[43mport[49m[43m,[49m[43m [49m[43mfamily[49m[43m,[49m[43m [49m[38;5;28;43mtype[39;49m[43m,[49m[43m [49m[43mproto[49m[43m,[49m[43m [49m[43mflags[49m[43m)[49m:
[1;32m    956[0m     af, socktype, proto, canonname, sa [38;5;241m=[39m res

[0;31mgaierror[0m: [Errno -3] Temporary failure in name resolution

During handling of the above exception, another exception occurred:

[0;31mNewConnectionError[0m                        Traceback (most recent call last)
File [0;32m/usr/lib/python3.10/site-packages/urllib3/connectionpool.py:703[0m, in [0;36mHTTPConnectionPool.urlopen[0;34m(self, method, url, body, headers, retries, redirect, assert_same_host, timeout, pool_timeout, release_conn, chunked, body_pos, **response_kw)[0m
[1;32m    702[0m [38;5;66;03m# Make the request on the httplib connection object.[39;00m
[0;32m--> 703[0m httplib_response [38;5;241m=[39m [38;5;28;43mself[39;49m[38;5;241;43m.[39;49m[43m_make_request[49m[43m([49m
[1;32m    704[0m [43m    [49m[43mconn[49m[43m,[49m
[1;32m    705[0m [43m    [49m[43mmethod[49m[43m,[49m
[1;32m    706[0m [43m    [49m[43murl[49m[43m,[49m
[1;32m    707[0m [43m    [49m[43mtimeout[49m[38;5;241;43m=[39;49m[43mtimeout_obj[49m[43m,[49m
[1;32m    708[0m [43m    [49m[43mbody[49m[38;5;241;43m=[39;49m[43mbody[49m[43m,[49m
[1;32m    709[0m [43m    [49m[43mheaders[49m[38;5;241;43m=[39;49m[43mheaders[49m[43m,[49m
[1;32m    710[0m [43m    [49m[43mchunked[49m[38;5;241;43m=[39;49m[43mchunked[49m[43m,[49m
[1;32m    711[0m [43m[49m[43m)[49m
[1;32m    713[0m [38;5;66;03m# If we're going to release the connection in ``finally:``, then[39;00m
[1;32m    714[0m [38;5;66;03m# the response doesn't need to know about the connection. Otherwise[39;00m
[1;32m    715[0m [38;5;66;03m# it will also try to release it and we'll have a double-release[39;00m
[1;32m    716[0m [38;5;66;03m# mess.[39;00m

File [0;32m/usr/lib/python3.10/site-packages/urllib3/connectionpool.py:386[0m, in [0;36mHTTPConnectionPool._make_request[0;34m(self, conn, method, url, timeout, chunked, **httplib_request_kw)[0m
[1;32m    385[0m [38;5;28;01mtry[39;00m:
[0;32m--> 386[0m     [38;5;28;43mself[39;49m[38;5;241;43m.[39;49m[43m_validate_conn[49m[43m([49m[43mconn[49m[43m)[49m
[1;32m    387[0m [38;5;28;01mexcept[39;00m (SocketTimeout, BaseSSLError) [38;5;28;01mas[39;00m e:
[1;32m    388[0m     [38;5;66;03m# Py2 raises this as a BaseSSLError, Py3 raises it as socket timeout.[39;00m

File [0;32m/usr/lib/python3.10/site-packages/urllib3/connectionpool.py:1042[0m, in [0;36mHTTPSConnectionPool._validate_conn[0;34m(self, conn)[0m
[1;32m   1041[0m [38;5;28;01mif[39;00m [38;5;129;01mnot[39;00m [38;5;28mgetattr[39m(conn, [38;5;124m"[39m[38;5;124msock[39m[38;5;124m"[39m, [38;5;28;01mNone[39;00m):  [38;5;66;03m# AppEngine might not have  `.sock`[39;00m
[0;32m-> 1042[0m     [43mconn[49m[38;5;241;43m.[39;49m[43mconnect[49m[43m([49m[43m)[49m
[1;32m   1044[0m [38;5;28;01mif[39;00m [38;5;129;01mnot[39;00m conn[38;5;241m.[39mis_verified:

File [0;32m/usr/lib/python3.10/site-packages/urllib3/connection.py:358[0m, in [0;36mHTTPSConnection.connect[0;34m(self)[0m
[1;32m    356[0m [38;5;28;01mdef[39;00m [38;5;21mconnect[39m([38;5;28mself[39m):
[1;32m    357[0m     [38;5;66;03m# Add certificate verification[39;00m
[0;32m--> 358[0m     [38;5;28mself[39m[38;5;241m.[39msock [38;5;241m=[39m conn [38;5;241m=[39m [38;5;28;43mself[39;49m[38;5;241;43m.[39;49m[43m_new_conn[49m[43m([49m[43m)[49m
[1;32m    359[0m     hostname [38;5;241m=[39m [38;5;28mself[39m[38;5;241m.[39mhost

File [0;32m/usr/lib/python3.10/site-packages/urllib3/connection.py:186[0m, in [0;36mHTTPConnection._new_conn[0;34m(self)[0m
[1;32m    185[0m [38;5;28;01mexcept[39;00m SocketError [38;5;28;01mas[39;00m e:
[0;32m--> 186[0m     [38;5;28;01mraise[39;00m NewConnectionError(
[1;32m    187[0m         [38;5;28mself[39m, [38;5;124m"[39m[38;5;124mFailed to establish a new connection: [39m[38;5;132;01m%s[39;00m[38;5;124m"[39m [38;5;241m%[39m e
[1;32m    188[0m     )
[1;32m    190[0m [38;5;28;01mreturn[39;00m conn

[0;31mNewConnectionError[0m: <urllib3.connection.HTTPSConnection object at 0x7fc30eb17ee0>: Failed to establish a new connection: [Errno -3] Temporary failure in name resolution

During handling of the above exception, another exception occurred:

[0;31mMaxRetryError[0m                             Traceback (most recent call last)
File [0;32m/usr/lib/python3.10/site-packages/requests/adapters.py:489[0m, in [0;36mHTTPAdapter.send[0;34m(self, request, stream, timeout, verify, cert, proxies)[0m
[1;32m    488[0m [38;5;28;01mif[39;00m [38;5;129;01mnot[39;00m chunked:
[0;32m--> 489[0m     resp [38;5;241m=[39m [43mconn[49m[38;5;241;43m.[39;49m[43murlopen[49m[43m([49m
[1;32m    490[0m [43m        [49m[43mmethod[49m[38;5;241;43m=[39;49m[43mrequest[49m[38;5;241;43m.[39;49m[43mmethod[49m[43m,[49m
[1;32m    491[0m [43m        [49m[43murl[49m[38;5;241;43m=[39;49m[43murl[49m[43m,[49m
[1;32m    492[0m [43m        [49m[43mbody[49m[38;5;241;43m=[39;49m[43mrequest[49m[38;5;241;43m.[39;49m[43mbody[49m[43m,[49m
[1;32m    493[0m [43m        [49m[43mheaders[49m[38;5;241;43m=[39;49m[43mrequest[49m[38;5;241;43m.[39;49m[43mheaders[49m[43m,[49m
[1;32m    494[0m [43m        [49m[43mredirect[49m[38;5;241;43m=[39;49m[38;5;28;43;01mFalse[39;49;00m[43m,[49m
[1;32m    495[0m [43m        [49m[43massert_same_host[49m[38;5;241;43m=[39;49m[38;5;28;43;01mFalse[39;49;00m[43m,[49m
[1;32m    496[0m [43m        [49m[43mpreload_content[49m[38;5;241;43m=[39;49m[38;5;28;43;01mFalse[39;49;00m[43m,[49m
[1;32m    497[0m [43m        [49m[43mdecode_content[49m[38;5;241;43m=[39;49m[38;5;28;43;01mFalse[39;49;00m[43m,[49m
[1;32m    498[0m [43m        [49m[43mretries[49m[38;5;241;43m=[39;49m[38;5;28;43mself[39;49m[38;5;241;43m.[39;49m[43mmax_retries[49m[43m,[49m
[1;32m    499[0m [43m        [49m[43mtimeout[49m[38;5;241;43m=[39;49m[43mtimeout[49m[43m,[49m
[1;32m    500[0m [43m    [49m[43m)[49m
[1;32m    502[0m [38;5;66;03m# Send the request.[39;00m
[1;32m    503[0m [38;5;28;01melse[39;00m:

File [0;32m/usr/lib/python3.10/site-packages/urllib3/connectionpool.py:787[0m, in [0;36mHTTPConnectionPool.urlopen[0;34m(self, method, url, body, headers, retries, redirect, assert_same_host, timeout, pool_timeout, release_conn, chunked, body_pos, **response_kw)[0m
[1;32m    785[0m     e [38;5;241m=[39m ProtocolError([38;5;124m"[39m[38;5;124mConnection aborted.[39m[38;5;124m"[39m, e)
[0;32m--> 787[0m retries [38;5;241m=[39m [43mretries[49m[38;5;241;43m.[39;49m[43mincrement[49m[43m([49m
[1;32m    788[0m [43m    [49m[43mmethod[49m[43m,[49m[43m [49m[43murl[49m[43m,[49m[43m [49m[43merror[49m[38;5;241;43m=[39;49m[43me[49m[43m,[49m[43m [49m[43m_pool[49m[38;5;241;43m=[39;49m[38;5;28;43mself[39;49m[43m,[49m[43m [49m[43m_stacktrace[49m[38;5;241;43m=[39;49m[43msys[49m[38;5;241;43m.[39;49m[43mexc_info[49m[43m([49m[43m)[49m[43m[[49m[38;5;241;43m2[39;49m[43m][49m
[1;32m    789[0m [43m[49m[43m)[49m
[1;32m    790[0m retries[38;5;241m.[39msleep()

File [0;32m/usr/lib/python3.10/site-packages/urllib3/util/retry.py:592[0m, in [0;36mRetry.increment[0;34m(self, method, url, response, error, _pool, _stacktrace)[0m
[1;32m    591[0m [38;5;28;01mif[39;00m new_retry[38;5;241m.[39mis_exhausted():
[0;32m--> 592[0m     [38;5;28;01mraise[39;00m MaxRetryError(_pool, url, error [38;5;129;01mor[39;00m ResponseError(cause))
[1;32m    594[0m log[38;5;241m.[39mdebug([38;5;124m"[39m[38;5;124mIncremented Retry for (url=[39m[38;5;124m'[39m[38;5;132;01m%s[39;00m[38;5;124m'[39m[38;5;124m): [39m[38;5;132;01m%r[39;00m[38;5;124m"[39m, url, new_retry)

[0;31mMaxRetryError[0m: HTTPSConnectionPool(host='api.makesens.co', port=443): Max retries exceeded with url: /ambiental/metricas/E2_00021/data?agg=1h&agg_type=mean&items=1000&max_ts=1675113120000&min_ts=1674249120000 (Caused by NewConnectionError('<urllib3.connection.HTTPSConnection object at 0x7fc30eb17ee0>: Failed to establish a new connection: [Errno -3] Temporary failure in name resolution'))

During handling of the above exception, another exception occurred:

[0;31mConnectionError[0m                           Traceback (most recent call last)
Cell [0;32mIn [5], line 1[0m
[0;32m----> 1[0m data [38;5;241m=[39m MakeSens[38;5;241m.[39mdownload_data([38;5;124m'[39m[38;5;124mE2_00021[39m[38;5;124m'[39m, fechaInicio, fechaFin, [38;5;124m'[39m[38;5;124mh[39m[38;5;124m'[39m)

File [0;32m~/.local/lib/python3.10/site-packages/MakeSens/MakeSens.py:36[0m, in [0;36mdownload_data[0;34m(id_device, start_date, end_date, sample_rate, format, fields)[0m
[1;32m     34[0m [38;5;28;01melse[39;00m:
[1;32m     35[0m     url [38;5;241m=[39m  [38;5;124mf[39m[38;5;124m'[39m[38;5;124mhttps://api.makesens.co/ambiental/metricas/[39m[38;5;132;01m{[39;00mid_device[38;5;132;01m}[39;00m[38;5;124m/data?agg=1[39m[38;5;132;01m{[39;00msample_rate[38;5;132;01m}[39;00m[38;5;124m&agg_type=mean&fields=[39m[38;5;132;01m{[39;00mfields[38;5;132;01m}[39;00m[38;5;124m&items=1000&max_ts=[39m[38;5;132;01m{[39;00m[38;5;28mstr[39m(end [38;5;241m*[39m [38;5;241m1000[39m)[38;5;132;01m}[39;00m[38;5;124m&min_ts=[39m[38;5;132;01m{[39;00m[38;5;28mstr[39m(tmin [38;5;241m*[39m [38;5;241m1000[39m)[38;5;132;01m}[39;00m[38;5;124m'[39m
[0;32m---> 36[0m rta [38;5;241m=[39m [43mrequests[49m[38;5;241;43m.[39;49m[43mget[49m[43m([49m[43murl[49m[43m)[49m[38;5;241m.[39mcontent
[1;32m     37[0m d [38;5;241m=[39m json[38;5;241m.[39mloads(rta)
[1;32m     38[0m [38;5;28;01mtry[39;00m:

File [0;32m/usr/lib/python3.10/site-packages/requests/api.py:73[0m, in [0;36mget[0;34m(url, params, **kwargs)[0m
[1;32m     62[0m [38;5;28;01mdef[39;00m [38;5;21mget[39m(url, params[38;5;241m=[39m[38;5;28;01mNone[39;00m, [38;5;241m*[39m[38;5;241m*[39mkwargs):
[1;32m     63[0m     [38;5;124mr[39m[38;5;124;03m"""Sends a GET request.[39;00m
[1;32m     64[0m 
[1;32m     65[0m [38;5;124;03m    :param url: URL for the new :class:`Request` object.[39;00m
[0;32m   (...)[0m
[1;32m     70[0m [38;5;124;03m    :rtype: requests.Response[39;00m
[1;32m     71[0m [38;5;124;03m    """[39;00m
[0;32m---> 73[0m     [38;5;28;01mreturn[39;00m [43mrequest[49m[43m([49m[38;5;124;43m"[39;49m[38;5;124;43mget[39;49m[38;5;124;43m"[39;49m[43m,[49m[43m [49m[43murl[49m[43m,[49m[43m [49m[43mparams[49m[38;5;241;43m=[39;49m[43mparams[49m[43m,[49m[43m [49m[38;5;241;43m*[39;49m[38;5;241;43m*[39;49m[43mkwargs[49m[43m)[49m

File [0;32m/usr/lib/python3.10/site-packages/requests/api.py:59[0m, in [0;36mrequest[0;34m(method, url, **kwargs)[0m
[1;32m     55[0m [38;5;66;03m# By using the 'with' statement we are sure the session is closed, thus we[39;00m
[1;32m     56[0m [38;5;66;03m# avoid leaving sockets open which can trigger a ResourceWarning in some[39;00m
[1;32m     57[0m [38;5;66;03m# cases, and look like a memory leak in others.[39;00m
[1;32m     58[0m [38;5;28;01mwith[39;00m sessions[38;5;241m.[39mSession() [38;5;28;01mas[39;00m session:
[0;32m---> 59[0m     [38;5;28;01mreturn[39;00m [43msession[49m[38;5;241;43m.[39;49m[43mrequest[49m[43m([49m[43mmethod[49m[38;5;241;43m=[39;49m[43mmethod[49m[43m,[49m[43m [49m[43murl[49m[38;5;241;43m=[39;49m[43murl[49m[43m,[49m[43m [49m[38;5;241;43m*[39;49m[38;5;241;43m*[39;49m[43mkwargs[49m[43m)[49m

File [0;32m/usr/lib/python3.10/site-packages/requests/sessions.py:587[0m, in [0;36mSession.request[0;34m(self, method, url, params, data, headers, cookies, files, auth, timeout, allow_redirects, proxies, hooks, stream, verify, cert, json)[0m
[1;32m    582[0m send_kwargs [38;5;241m=[39m {
[1;32m    583[0m     [38;5;124m"[39m[38;5;124mtimeout[39m[38;5;124m"[39m: timeout,
[1;32m    584[0m     [38;5;124m"[39m[38;5;124mallow_redirects[39m[38;5;124m"[39m: allow_redirects,
[1;32m    585[0m }
[1;32m    586[0m send_kwargs[38;5;241m.[39mupdate(settings)
[0;32m--> 587[0m resp [38;5;241m=[39m [38;5;28;43mself[39;49m[38;5;241;43m.[39;49m[43msend[49m[43m([49m[43mprep[49m[43m,[49m[43m [49m[38;5;241;43m*[39;49m[38;5;241;43m*[39;49m[43msend_kwargs[49m[43m)[49m
[1;32m    589[0m [38;5;28;01mreturn[39;00m resp

File [0;32m/usr/lib/python3.10/site-packages/requests/sessions.py:701[0m, in [0;36mSession.send[0;34m(self, request, **kwargs)[0m
[1;32m    698[0m start [38;5;241m=[39m preferred_clock()
[1;32m    700[0m [38;5;66;03m# Send the request[39;00m
[0;32m--> 701[0m r [38;5;241m=[39m [43madapter[49m[38;5;241;43m.[39;49m[43msend[49m[43m([49m[43mrequest[49m[43m,[49m[43m [49m[38;5;241;43m*[39;49m[38;5;241;43m*[39;49m[43mkwargs[49m[43m)[49m
[1;32m    703[0m [38;5;66;03m# Total elapsed time of the request (approximately)[39;00m
[1;32m    704[0m elapsed [38;5;241m=[39m preferred_clock() [38;5;241m-[39m start

File [0;32m/usr/lib/python3.10/site-packages/requests/adapters.py:565[0m, in [0;36mHTTPAdapter.send[0;34m(self, request, stream, timeout, verify, cert, proxies)[0m
[1;32m    561[0m     [38;5;28;01mif[39;00m [38;5;28misinstance[39m(e[38;5;241m.[39mreason, _SSLError):
[1;32m    562[0m         [38;5;66;03m# This branch is for urllib3 v1.22 and later.[39;00m
[1;32m    563[0m         [38;5;28;01mraise[39;00m SSLError(e, request[38;5;241m=[39mrequest)
[0;32m--> 565[0m     [38;5;28;01mraise[39;00m [38;5;167;01mConnectionError[39;00m(e, request[38;5;241m=[39mrequest)
[1;32m    567[0m [38;5;28;01mexcept[39;00m ClosedPoolError [38;5;28;01mas[39;00m e:
[1;32m    568[0m     [38;5;28;01mraise[39;00m [38;5;167;01mConnectionError[39;00m(e, request[38;5;241m=[39mrequest)

[0;31mConnectionError[0m: HTTPSConnectionPool(host='api.makesens.co', port=443): Max retries exceeded with url: /ambiental/metricas/E2_00021/data?agg=1h&agg_type=mean&items=1000&max_ts=1675113120000&min_ts=1674249120000 (Caused by NewConnectionError('<urllib3.connection.HTTPSConnection object at 0x7fc30eb17ee0>: Failed to establish a new connection: [Errno -3] Temporary failure in name resolution'))
ConnectionError: HTTPSConnectionPool(host='api.makesens.co', port=443): Max retries exceeded with url: /ambiental/metricas/E2_00021/data?agg=1h&agg_type=mean&items=1000&max_ts=1675113120000&min_ts=1674249120000 (Caused by NewConnectionError('<urllib3.connection.HTTPSConnection object at 0x7fc30eb17ee0>: Failed to establish a new connection: [Errno -3] Temporary failure in name resolution'))

